Workbook

Sheet Olah Data 3 -Form Responses (3)
K1: A. Kejelasan Konsep Framework | P1: Bagian B: Kelengkapan Komponen Framework | U1: C. Kesesuaian Integrasi Framework | Z1: D. Relevansi Indikator | AE1: E. Keterpaduan Alur Proses | AJ1: F. Potensi Penerapan Organisasi | AO1: G. Kejelasan Output Framework
A2: Timestamp | B2: 1. Nama Lengkap | C2: Jenis Kelamin | D2: 2. Pekerjaan Saat ini : | E2: 3. Jenis Bidang Industri (berdasarkan KLBI) | F2: 5. No Kontak (Opsional) kebutuhan pengiriman Ovo bila terpilih secara acak [08xxx] | G2: 6. Bidang Keahlian | H2: 6.A Keahlian Utama | I2: 7. Pengalaman Profesional dibidang IT | J2: 8. Pengalaman dengan Framework | K2: 1. Konsep framework perencanaan strategis TI terintegrasi yang dikembangkan dalam penelitian ini mudah dipahami. Jenis Pertanyaan: Linear scale (1–5) Skala: 1 = Sangat Tidak Setuju 5 = Sangat Setuju | L2: 2. Tujuan utama framework ini dijelaskan secara jelas dan sesuai dengan kebutuhan perencanaan strategis TI. Jenis Pertanyaan: Linear scale (1–5) Skala: 1 = Sangat Tidak Setuju 5 = Sangat Setuju | M2: 3. Ruang lingkup framework ini sudah tergambar dengan jelas, mencakup strategi SI/TI, enterprise architecture, tata kelola TI, risiko, dan pengukuran kinerja. Jenis Pertanyaan: Linear scale (1–5) Skala: 1 = Sangat Tidak Setuju 5 = Sangat Setuju | N2: 4. Hubungan antara masalah penelitian dan solusi framework yang dikembangkan sudah terlihat jelas. Jenis Pertanyaan: Linear scale (1–5) Skala: 1 = Sangat Tidak Setuju 5 = Sangat Setuju | O2: 5. Framework ini memiliki dasar pemikiran yang logis dalam mengintegrasikan Ward and Peppard, TOGAF, dan COBIT 2019. Jenis Pertanyaan: Linear scale (1–5) Skala: 1 = Sangat Tidak Setuju 5 = Sangat Setuju | P2: 1. Komponen analisis strategis SI/TI dalam framework ini sudah memadai untuk mengidentifikasi kebutuhan organisasi Jenis Pertanyaan: Linear scale (1–5) Skala: 1 = Sangat Tidak Setuju 5 = Sangat Setuju | Q2: 2. Komponen portofolio aplikasi dalam framework ini sudah memadai untuk menentukan prioritas aplikasi masa depan. Jenis Pertanyaan: Linear scale (1–5) Skala: 1 = Sangat Tidak Setuju 5 = Sangat Setuju | R2: 3. Komponen enterprise architecture dalam framework ini sudah mencakup arsitektur bisnis, data, aplikasi, dan teknologi. Jenis Pertanyaan: Linear scale (1–5) Skala: 1 = Sangat Tidak Setuju 5 = Sangat Setuju | S2: 4. Komponen tata kelola TI, capability assessment, risk control, dan performance measurement sudah tercakup dengan baik dalam framework ini. Jenis Pertanyaan: Linear scale (1–5) Skala: 1 = Sangat Tidak Setuju 5 = Sangat Setuju | T2: 5. Secara keseluruhan, komponen framework ini sudah lengkap untuk mendukung penyusunan IT Master Plan dan roadmap transformasi digital. Jenis Pertanyaan: Linear scale (1–5) Skala: 1 = Sangat Tidak Setuju 5 = Sangat Setuju | U2: 1. Integrasi Ward and Peppard, TOGAF, dan COBIT 2019 dalam framework ini sudah sesuai dengan karakteristik masing-masing framework. Jenis Pertanyaan: Linear scale (1–5) Skala: 1 = Sangat Tidak Setuju 5 = Sangat Setuju | V2: 2. Ward and Peppard sudah ditempatkan secara tepat sebagai dasar analisis dan formulasi strategi SI/TI. Jenis Pertanyaan: Linear scale (1–5) Skala: 1 = Sangat Tidak Setuju 5 = Sangat Setuju | W2: 3. TOGAF sudah ditempatkan secara tepat sebagai dasar penyusunan enterprise architecture. Jenis Pertanyaan: Linear scale (1–5) Skala: 1 = Sangat Tidak Setuju 5 = Sangat Setuju | X2: 4. COBIT 2019 sudah ditempatkan secara tepat sebagai dasar tata kelola, capability assessment, risiko, kontrol, dan pengukuran kinerja TI. Jenis Pertanyaan: Linear scale (1–5) Skala: 1 = Sangat Tidak Setuju 5 = Sangat Setuju | Y2: 5. Integrasi ketiga framework dalam model ini saling melengkapi dan tidak menimbulkan tumpang tindih fungsi yang berlebihan. Jenis Pertanyaan: Linear scale (1–5) Skala: 1 = Sangat Tidak Setuju 5 = Sangat Setuju | Z2: 1. Indikator strategic alignment relevan untuk menilai keselarasan antara tujuan organisasi dan strategi TI. Jenis Pertanyaan: Linear scale (1–5) Skala: 1 = Sangat Tidak Setuju 5 = Sangat Setuju | AA2: 2. Indikator IS/IT portfolio planning relevan untuk menilai prioritas aplikasi dan kebutuhan sistem informasi organisasi. Jenis Pertanyaan: Linear scale (1–5) Skala: 1 = Sangat Tidak Setuju 5 = Sangat Setuju | AB2: 3. Indikator enterprise architecture blueprint relevan untuk menilai kelengkapan rancangan arsitektur bisnis, data, aplikasi, dan teknologi. Jenis Pertanyaan: Linear scale (1–5) Skala: 1 = Sangat Tidak Setuju 5 = Sangat Setuju | AC2: 4. Indikator governance objective mapping, capability assessment, risk control, dan performance measurement relevan untuk menilai tata kelola dan kesiapan TI. Jenis Pertanyaan: Linear scale (1–5) Skala: 1 = Sangat Tidak Setuju 5 = Sangat Setuju | AD2: 5. Secara keseluruhan, indikator dalam framework ini sudah sesuai untuk menilai kelayakan framework perencanaan strategis TI terintegrasi. Jenis Pertanyaan: Linear scale (1–5) Skala: 1 = Sangat Tidak Setuju 5 = Sangat Setuju | AE2: 1. Alur framework dimulai dari analisis kebutuhan organisasi secara sistematis dan mudah diikuti. Jenis Pertanyaan: Linear scale (1–5) Skala: 1 = Sangat Tidak Setuju 5 = Sangat Setuju | AF2: 2. Alur framework mampu menghubungkan analisis kebutuhan organisasi dengan formulasi strategi SI/TI. Jenis Pertanyaan: Linear scale (1–5) Skala: 1 = Sangat Tidak Setuju 5 = Sangat Setuju | AG2: 3. Alur framework mampu menghubungkan strategi SI/TI dengan penyusunan portofolio aplikasi dan enterprise architecture. Jenis Pertanyaan: Linear scale (1–5) Skala: 1 = Sangat Tidak Setuju 5 = Sangat Setuju | AH2: 4. Alur framework mampu menghubungkan enterprise architecture dengan tata kelola TI, capability assessment, risk control, dan KPI. Jenis Pertanyaan: Linear scale (1–5) Skala: 1 = Sangat Tidak Setuju 5 = Sangat Setuju | AI2: 5. Setiap tahapan framework memiliki hubungan input, proses, dan output yang jelas. Jenis Pertanyaan: Linear scale (1–5) Skala: 1 = Sangat Tidak Setuju 5 = Sangat Setuju | AJ2: 1. Framework ini berpotensi diterapkan pada organisasi yang membutuhkan perencanaan strategis TI. Jenis Pertanyaan: Linear scale (1–5) Skala: 1 = Sangat Tidak Setuju 5 = Sangat Setuju | AK2: 2. Framework ini dapat digunakan untuk mendukung penyusunan IT Master Plan organisasi. Jenis Pertanyaan: Linear scale (1–5) Skala: 1 = Sangat Tidak Setuju 5 = Sangat Setuju | AL2: 3. Framework ini dapat digunakan untuk mendukung penyusunan roadmap transformasi digital dan blueprint enterprise architecture. Jenis Pertanyaan: Linear scale (1–5) Skala: 1 = Sangat Tidak Setuju 5 = Sangat Setuju | AM2: 4. Framework ini dapat membantu organisasi menentukan prioritas program, proyek, dan investasi TI. Jenis Pertanyaan: Linear scale (1–5) Skala: 1 = Sangat Tidak Setuju 5 = Sangat Setuju | AN2: 5. Framework ini cukup praktis untuk digunakan oleh tim perencana TI, manajemen TI, auditor TI, atau konsultan TI. Jenis Pertanyaan: Linear scale (1–5) Skala: 1 = Sangat Tidak Setuju 5 = Sangat Setuju | AO2: 1. Output berupa strategi SI/TI dalam framework ini sudah jelas dan mudah dipahami. Jenis Pertanyaan: Linear scale (1–5) Skala: 1 = Sangat Tidak Setuju 5 = Sangat Setuju | AP2: 2. Output berupa portofolio aplikasi dan prioritas aplikasi sudah jelas untuk mendukung kebutuhan organisasi. Jenis Pertanyaan: Linear scale (1–5) Skala: 1 = Sangat Tidak Setuju 5 = Sangat Setuju | AQ2: 3. Output berupa blueprint enterprise architecture sudah jelas dan mencakup arsitektur bisnis, data, aplikasi, dan teknologi. Jenis Pertanyaan: Linear scale (1–5) Skala: 1 = Sangat Tidak Setuju 5 = Sangat Setuju | AR2: 4. Output berupa governance objectives, capability level, risk register, control mapping, dan KPI sudah jelas untuk mendukung tata kelola TI. Jenis Pertanyaan: Linear scale (1–5) Skala: 1 = Sangat Tidak Setuju 5 = Sangat Setuju | AS2: 5. Secara keseluruhan, output framework ini dapat digunakan sebagai dasar penyusunan dokumen perencanaan strategis TI organisasi. Jenis Pertanyaan: Linear scale (1–5) Skala: 1 = Sangat Tidak Setuju 5 = Sangat Setuju | AT2: 1. Apakah menurut Anda model Integrasi Perencanaan Strategis TI sudah menggambarkan hubungan logis antara strategi, arsitektur, dan tata kelola TI? | AU2: 2. Komponen mana yang menurut Anda perlu diperbaiki atau disempurnakan? | AV2: 3. Apakah framework ini dapat diterapkan di konteks organisasi Anda? Mengapa? | AW2: 4. Saran tambahan untuk pengembangan model Integrasi Perencanaan Strategis TI di masa mendatang: | AX2: Filter 1 (Rekomendasi sebagai Praktisi & Akademisi) terkait Perencanaan strategis TI | AY2: Fiilter ke 2 , berdasarkan perencanaan strategis TI | AZ2: Rata-2 Faktor A | BA2: Rata-2 Faktor B | BB2: Rata-2 Faktor C | BC2: Rata-2 Faktor D | BD2: Rata-2 Faktor E | BE2: Rata-2 Faktor F | BF2: Rata-2 Faktor G | BG2: Kategori Relevan Faktor A | BH2: Kategori Relevan Faktor B | BI2: Kategori Relevan Faktor C | BJ2: Kategori Relevan Faktor D | BK2: Kategori Relevan Faktor E | BL2: Kategori Relevan Faktor F | BM2: Kategori Relevan Faktor G
K3: COBIT 2019 | AX3: =FALSE() -> FALSE | AZ3: =AVERAGE(K3:O3) -> #DIV/0! | BG3: =IF(AZ3>=4,1,0) -> #DIV/0!
K4: 1 | L4: 2 | M4: 3 | N4: 4 | O4: 5 | P4: 1 | Q4: 2 | R4: 3 | S4: 4 | T4: 5 | U4: 1 | V4: 2 | W4: 3 | X4: 4 | Y4: 5 | Z4: 1 | AA4: 2 | AB4: 3 | AC4: 4 | AD4: 5 | AX4: =FALSE() -> FALSE | AZ4: =AVERAGE(K4:O4) -> 3 | BG4: =IF(AZ4>=4,1,0) -> 0
A5: 46077.401 | B5: Expert 1 | C5: Pria | D5: Akademisi (Guru, Dosen), Konsultan IT, Praktisi IT | E5: 10.Informasi dan Komunikasi | G5: Tata Kelola TI/ IT Governance, Arsitektur Enterprise, Perencanaan Strategis TI, Audit & Manajemen TI, Pengembang Aplikasi | H5: Pakar tata kelola TI atau COBIT | I5: > 20 Tahun | J5: TOGAF, COBIT, ITIL | K5: 5 | L5: 5 | M5: 5 | N5: 5 | O5: 5 | P5: 5 | Q5: 5 | R5: 5 | S5: 5 | T5: 5 | U5: 5 | V5: 5 | W5: 5 | X5: 5 | Y5: 5 | Z5: 5 | AA5: 5 | AB5: 5 | AC5: 5 | AD5: 5 | AE5: 4 | AF5: 5 | AG5: 5 | AH5: 5 | AI5: 5 | AJ5: 5 | AK5: 4 | AL5: 5 | AM5: 5 | AN5: 5 | AO5: 5 | AP5: 5 | AQ5: 4 | AT5: Ya, model Integrasi Perencanaan Strategis TI sudah menunjukkan hubungan logis karena strategi menetapkan arah, arsitektur menerjemahkannya menjadi desain kapabilitas, dan tata kelola memastikan pelaksanaan serta pengendaliannya berjalan selaras dan terukur, sebagaimana selaras dengan prinsip dalam COBIT 2019 dan TOGAF. | AU5: Komponen yang perlu disempurnakan adalah keterlacakan antara strategi, arsitektur, dan tata kelola, serta penguatan mekanisme pengukuran kinerja dan umpan balik agar evaluasi benar-benar mendorong perbaikan strategis, bukan sekadar formalitas laporan. | AV5: Ya, framework ini dapat diterapkan karena membantu menyelaraskan strategi, arsitektur, dan tata kelola TI secara terstruktur serta dapat diadaptasi dengan praktik seperti COBIT 2019 dan ITIL 4 untuk meningkatkan kematangan organisasi secara bertahap. | AW5: Ke depan, model Integrasi Perencanaan Strategis TI perlu dikembangkan dengan menambahkan mekanisme keterlacakan end-to-end dari tujuan strategis hingga indikator kinerja operasional, memperkuat integrasi manajemen risiko dan kepatuhan sejak tahap perancangan arsitektur, serta memasukkan pendekatan adaptif berbasis data dan evaluasi berkelanjutan agar model lebih responsif terhadap perubahan bisnis dan teknologi. | AX5: =TRUE() -> TRUE | AY5: =FALSE() -> FALSE | AZ5: =AVERAGE(K5:O5) -> 5 | BA5: =AVERAGE(P5:T5) -> 5 | BB5: =AVERAGE(U5:Y5) -> 5 | BC5: =AVERAGE(Z5:AD5) -> 5 | BD5: =AVERAGE(AE5:AI5) -> 4.8 | BE5: =AVERAGE(AJ5:AN5) -> 4.8 | BF5: =AVERAGE(AO5:AS5) -> 4.6666667 | BG5: =IF(AZ5>=4,1,0) -> 1 | BH5: =IF(BA5>=4,1,0) -> 1 | BI5: =IF(BB5>=4,1,0) -> 1 | BJ5: =IF(BC5>=4,1,0) -> 1 | BK5: =IF(BD5>=4,1,0) -> 1 | BL5: =IF(BE5>=4,1,0) -> 1 | BM5: =IF(BF5>=4,1,0) -> 1
A6: 46077.402 | B6: Andi Rukmana | C6: Pria | D6: Other : | E6: 15. Administrasi Pemerintahan, Pertahanan, dan Jaminan Sosial Wajib, | F6: 089531825682 | G6: Perencanaan Strategis TI, Audit & Manajemen TI, Infrastructure IT, Cybersecurity, | I6: < 5 Tahun | J6: COBIT | K6: 5 | L6: 5 | M6: 4 | N6: 5 | O6: 4 | P6: 5 | Q6: 5 | R6: 4 | S6: 5 | T6: 4 | U6: 5 | V6: 5 | W6: 4 | X6: 5 | Y6: 5 | Z6: 3 | AA6: 4 | AB6: 4 | AC6: 4 | AD6: 4 | AF6: 5 | AG6: 5 | AH6: 5 | AI6: 5 | AJ6: 5 | AK6: 4 | AL6: 5 | AM6: 5 | AN6: 5 | AO6: 5 | AP6: 5 | AQ6: 4 | AT6: a, model sudah menggambarkan hubungan yang logis dan sistematis. Strategi TI diturunkan dari strategi bisnis (layer perencanaan), kemudian diterjemahkan ke dalam desain arsitektur TI sebagai blueprint implementasi, dan akhirnya dikontrol serta dimonitor melalui tata kelola dan pengukuran kinerja TI. Alur ini menunjukkan keterkaitan yang konsisten antara perencanaan, implementasi, dan evaluasi. Namun, kejelasan mekanisme integrasi antar-layer masih perlu dipertegas dalam bentuk alur proses atau model visual yang lebih operasional. | AU6: Beberapa komponen yang dapat disempurnakan: Mekanisme transisi dari strategi ke arsitektur (agar tidak hanya konseptual tetapi operasional) Penjelasan peran dan tanggung jawab (governance structure) Integrasi manajemen perubahan (change management) Indikator pengukuran keberhasilan integrasi framework Penambahan contoh studi kasus atau template implementasi juga akan meningkatkan kejelasan praktis. | AV6: Framework ini dapat diterapkan, terutama pada organisasi dengan tingkat kematangan TI menengah hingga tinggi. Karena framework mengintegrasikan strategi, arsitektur, dan tata kelola, ia cocok untuk organisasi yang membutuhkan alignment dan kontrol TI yang kuat. Namun, untuk organisasi dengan sumber daya terbatas, implementasi perlu dilakukan secara bertahap (phased approach) agar tidak membebani struktur organisasi. | AW6: Beberapa saran pengembangan: Menyederhanakan model agar lebih mudah diadopsi organisasi skala kecil–menengah Menambahkan panduan implementasi bertahap (roadmap integrasi framework) Mengembangkan alat ukur kesiapan organisasi (IT maturity assessment) Menguji model pada berbagai sektor industri untuk validasi empiris | AX6: =FALSE() -> FALSE | AY6: =TRUE() -> TRUE | AZ6: =AVERAGE(K6:O6) -> 4.6 | BG6: =IF(AZ6>=4,1,0) -> 1
A7: 46077.403 | B7: Winny Purbaratri | C7: Wanita | D7: Akademisi (Guru, Dosen) | E7: 16.Pendidikan | F7: 081219203209 | G7: Tata Kelola TI/ IT Governance, Pengembang Aplikasi | I7: 16-20 Tahun | J7: COBIT, SPBE | K7: 5 | L7: 4 | M7: 5 | N7: 4 | O7: 5 | P7: 4 | Q7: 4 | R7: 4 | S7: 5 | T7: 5 | U7: 5 | V7: 5 | W7: 5 | X7: 5 | Y7: 5 | Z7: 4 | AA7: 4 | AB7: 4 | AC7: 4 | AD7: 4 | AF7: 4 | AG7: 3 | AH7: 4 | AI7: 4 | AJ7: 4 | AK7: 4 | AL7: 4 | AM7: 3 | AN7: 4 | AO7: 4 | AP7: 4 | AQ7: 4 | AT7: Ya, secara konseptual sudah logis. Strategi bisnis diturunkan ke strategi TI, diterjemahkan dalam arsitektur, lalu dikontrol melalui tata kelola. Ini sejalan dengan praktik seperti COBIT yang menekankan alignment dan value delivery. Namun, model perlu memastikan ada mekanisme evaluasi dan feedback. | AU7: Integrasi manajemen risiko dan budaya digital | AV7: Bisa, terutama di organisasi besar atau sektor yang regulatif. Namun perlu disesuaikan dengan skala dan budaya organisasi agar tidak terlalu birokratis. | AW7: Integrasi data & AI governance , Agile governance dan memasukkan aspek sustainability TI. Intinya, modelnya sudah baik, tetapi perlu lebih adaptif, terukur, dan relevan dengan dinamika transformasi digital. | AX7: =FALSE() -> FALSE | AY7: =TRUE() -> TRUE | AZ7: =AVERAGE(K7:O7) -> 4.6 | BG7: =IF(AZ7>=4,1,0) -> 1
A8: 46077.405 | B8: Expert 2 | C8: Pria | D8: Akademisi (Guru, Dosen), Praktisi IT | E8: 10.Informasi dan Komunikasi | G8: Tata Kelola TI/ IT Governance, Audit & Manajemen TI, Cybersecurity | H8: Pakar tata kelola TI atau COBIT | I8: 11-15 Tahun | J8: TOGAF, COBIT, ITIL | K8: 5 | L8: 5 | M8: 5 | N8: 5 | O8: 5 | P8: 5 | Q8: 5 | R8: 5 | S8: 5 | T8: 5 | U8: 5 | V8: 5 | W8: 5 | X8: 5 | Y8: 5 | Z8: 5 | AA8: 5 | AB8: 5 | AC8: 5 | AD8: 5 | AE8: 4 | AF8: 5 | AG8: 4 | AH8: 4 | AI8: 4 | AJ8: 4 | AK8: 4 | AL8: 3 | AM8: 4 | AN8: 4 | AO8: 4 | AP8: 4 | AQ8: 4 | AT8: Secara konseptual: YA, sangat logis, karena: Strategi → menentukan arah Arsitektur → menerjemahkan arah menjadi desain Tata kelola → mengawasi agar desain dijalankan dengan benar Hubungan ini bersifat: Top-down (alignment strategis) Bottom-up (feedback operasional) Continuous improvement | AU8: 1️⃣ Penyelarasan Strategi Bisnis dan Strategi TI 🔎 Masalah Umum: Strategi TI dibuat setelah strategi bisnis selesai, bukan sebagai bagian integral. Tidak ada cascading objective yang terukur. 🔧 Perlu Disempurnakan: Mapping eksplisit antara business objective dan IT objective. Gunakan pendekatan seperti: Balanced Scorecard Strategy Map Alignment model dari Michael Porter (value chain thinking) Tanpa alignment yang jelas, arsitektur dan governance akan kehilangan arah. 2️⃣ Enterprise Architecture sebagai Jembatan Strategi Sering kali arsitektur hanya menjadi dokumentasi teknis. 🔎 Masalah: Tidak berbasis capability Tidak terhubung dengan portfolio investasi Tidak digunakan dalam decision making 🔧 Perlu Disempurnakan: Gunakan capability-based planning Integrasikan arsitektur dengan roadmap transformasi Terapkan prinsip dari The Open Group melalui TOGAF yang menekankan Architecture Vision dan Governance Arsitektur harus menjadi decision framework, bukan sekadar blueprint. 3️⃣ Tata Kelola TI (IT Governance) 🔎 Masalah: Governance terlalu fokus compliance Tidak terhubung dengan value realization Tidak ada pengukuran benefit Framework seperti ISACA melalui COBIT sebenarnya sudah menekankan: Value delivery Risk optimization Resource optimization 🔧 Perlu Disempurnakan: Perjelas decision rights (RACI) Integrasikan risk appetite ke perencanaan Buat KPI governance yang terhubung ke outcome bisnis 4️⃣ Mekanisme Feedback Loop (Yang Paling Sering Hilang) Ini komponen yang paling sering kurang matang. Model integrasi yang baik harus memiliki: Monitoring kinerja Review arsitektur berkala Audit berbasis risiko Continuous improvement Tanpa feedback loop, model hanya berjalan satu arah (top-down), padahal lingkungan TI sangat dinamis. 5️⃣ Manajemen Risiko dan Cybersecurity Integration Banyak model memisahkan risk management dari perencanaan strategis. Padahal: Risk appetite memengaruhi arsitektur Security requirement memengaruhi desain teknologi Compliance memengaruhi governance structure Integrasi dengan risk-based approach sangat penting agar model menjadi resilien. | AV8: 1️⃣ Karakter Organisasi Digital Membutuhkan Alignment Tinggi Organisasi berbasis teknologi memiliki: Ketergantungan tinggi pada infrastruktur TI Siklus inovasi cepat Risiko keamanan dan privasi tinggi Kebutuhan scalability Karena itu, hubungan antara: Strategi → Arsitektur → Tata Kelola menjadi krusial untuk menjaga konsistensi arah dan kontrol. Framework seperti COBIT dari ISACA relevan karena menekankan value delivery dan risk optimization. 2️⃣ Enterprise Architecture sebagai Enabler Transformasi Dalam organisasi teknologi, perubahan produk dan platform sangat cepat. Tanpa arsitektur yang terstruktur (misalnya pendekatan dari The Open Group melalui TOGAF): Sistem menjadi silo Integrasi mahal Technical debt meningkat Karena itu, arsitektur menjadi jembatan strategis yang wajib ada. 3️⃣ Governance untuk Menjaga Kecepatan dan Kontrol Organisasi digital sering menghadapi dilema: Speed vs Control Framework integrasi memungkinkan: Inovasi tetap cepat Risiko tetap terkelola Investasi tetap terarah Tanpa governance yang jelas, transformasi digital justru bisa meningkatkan eksposur risiko. 4️⃣ Namun Perlu Adaptasi Framework ini tidak bisa diterapkan secara “textbook”. Penyesuaian yang biasanya diperlukan: Lebih agile (iterative planning) Integrasi DevSecOps Decision-making lebih desentralistik Continuous performance monitoring Model tradisional yang terlalu birokratis justru akan memperlambat organisasi digital. | AW8: 1️⃣ Integrasi Agile & Adaptive Strategy Model ke depan tidak bisa lagi bersifat linear (5-year static plan). Perlu ditambahkan: Rolling strategy (review kuartalan) Dynamic portfolio management Scenario planning Pendekatan seperti emergent strategy dari Henry Mintzberg dapat melengkapi pendekatan perencanaan formal yang terlalu rigid. 2️⃣ Capability-Based & Value-Driven Planning Model perlu bergeser dari: “Perencanaan proyek TI” Menjadi: “Pengembangan kapabilitas bisnis berbasis digital” Pendekatan Enterprise Architecture dari The Open Group melalui TOGAF bisa diperkuat dengan: Business capability mapping Value stream mapping Benefit realization tracking Fokus bukan pada sistem, tetapi pada outcome bisnis. 3️⃣ Embedded Risk & Cyber Resilience Ke depan, risiko bukan sekadar komponen tambahan. Model perlu: Integrasi risk appetite dalam strategy cascade Cyber resilience by design Continuous control monitoring Framework seperti ISACA melalui COBIT sudah mengarah ke risk optimization, tetapi perlu dipadukan dengan pendekatan resilience dan threat intelligence modern. 4️⃣ Integrasi Data Governance & AI Governance Transformasi digital saat ini berbasis data dan AI. Model masa depan perlu memasukkan: Data ownership clarity Data quality accountability AI ethics & governance layer Responsible AI framework Tanpa ini, strategi TI tidak akan relevan dalam era AI-driven organization. 5️⃣ Sustainability & Green IT Dimension Ke depan, strategi TI harus mempertimbangkan: Energy efficiency Carbon footprint IT infrastructure Sustainable cloud strategy Integrasi ESG (Environmental, Social, Governance) ke dalam model perencanaan strategis TI akan menjadi keharusan. 6️⃣ Real-Time Performance & Feedback Loop Model klasik sering berhenti di tahap perencanaan dan governance formal. Pengembangan ke depan perlu: Real-time KPI dashboard Strategy-to-execution traceability Continuous architecture review Digital twin untuk enterprise model Sehingga hubungan Strategi → Arsitektur → Governance menjadi siklus dinamis, bukan struktur statis. | AX8: =TRUE() -> TRUE | AY8: =FALSE() -> FALSE | AZ8: =AVERAGE(K8:O8) -> 5 | BA8: =AVERAGE(P8:T8) -> 5 | BB8: =AVERAGE(U8:Y8) -> 5 | BC8: =AVERAGE(Z8:AD8) -> 5 | BD8: =AVERAGE(AE8:AI8) -> 4.2 | BE8: =AVERAGE(AJ8:AN8) -> 3.8 | BF8: =AVERAGE(AO8:AS8) -> 4 | BG8: =IF(AZ8>=4,1,0) -> 1 | BH8: =IF(BA8>=4,1,0) -> 1 | BI8: =IF(BB8>=4,1,0) -> 1 | BJ8: =IF(BC8>=4,1,0) -> 1 | BK8: =IF(BD8>=4,1,0) -> 1 | BL8: =IF(BE8>=4,1,0) -> 0 | BM8: =IF(BF8>=4,1,0) -> 1
A9: 46077.406 | B9: Nurasiah | C9: Wanita | D9: Akademisi (Guru, Dosen) | E9: 16.Pendidikan | F9: +62 856-9795-6928 | G9: Perencanaan Strategis TI | I9: 5-10 Tahun | J9: COBIT | K9: 3 | L9: 4 | M9: 4 | N9: 4 | O9: 5 | P9: 4 | Q9: 3 | R9: 5 | S9: 5 | T9: 4 | U9: 4 | V9: 4 | W9: 5 | X9: 5 | Y9: 5 | Z9: 4 | AA9: 4 | AB9: 3 | AC9: 5 | AD9: 5 | AF9: 5 | AG9: 5 | AH9: 5 | AI9: 5 | AJ9: 5 | AK9: 4 | AL9: 5 | AM9: 5 | AN9: 5 | AO9: 5 | AP9: 5 | AQ9: 4 | AT9: sudah sangat menggambarkan hubungan yang logis | AU9: Komponen Manajemen Risiko dan Keamanan Informasi | AV9: bisa diterapkan | AW9: Integrasi dengan Kerangka Kerja Tata Kelola TI Global karena Integrasi ini dapat memperkuat aspek tata kelola, manajemen layanan TI, serta keselarasan arsitektur enterprise dengan strategi organisasi melakukan Pendekatan Berbasis Agile dan Adaptive Strategy | AX9: =FALSE() -> FALSE | AY9: =TRUE() -> TRUE | AZ9: =AVERAGE(K9:O9) -> 4 | BG9: =IF(AZ9>=4,1,0) -> 1
A10: 46077.41 | B10: Agun Guntara | C10: Pria | D10: Akademisi (Guru, Dosen) | E10: 16.Pendidikan | F10: 08987922009 | G10: Arsitektur Enterprise, Perencanaan Strategis TI | I10: 5-10 Tahun | J10: TOGAF | K10: 5 | L10: 4 | M10: 4 | N10: 4 | O10: 4 | P10: 5 | Q10: 5 | R10: 5 | S10: 5 | T10: 4 | U10: 5 | V10: 5 | W10: 4 | X10: 5 | Y10: 5 | Z10: 4 | AA10: 4 | AB10: 5 | AC10: 4 | AD10: 4 | AF10: 2 | AG10: 2 | AH10: 3 | AI10: 3 | AJ10: 4 | AK10: 3 | AL10: 2 | AM10: 2 | AN10: 3 | AO10: 3 | AP10: 4 | AQ10: 3 | AT10: model ini memenuhi kaidah "The Golden Thread" dalam manajemen TI, Model ini berhasil menjembatani gap antara niat strategis pimpinan organisasi dengan realitas teknis di lapangan, sehingga TI tidak lagi menjadi "pulau terpencil", melainkan bagian integral dari pencapaian tujuan organisasi. | AU10: model integrasi ini sudah sangat kuat secara teoretis, namun ada dua area krusial yang perlu disempurnakan agar lebih adaptif dengan realitas industri saat ini: 1. Integrasi Agilitas (Agile & DevOps) 2. Penekanan pada Data-Driven Governance 3. Aspek Manusia dan Budaya (Change Management) | AV10: Dalam konteks perguruan tinggi, framework integrasi ini sangat relevan dan layak diterapkan karena institusi pendidikan merupakan ekosistem yang kompleks dengan beragam kepentingan. | AW10: Saya melihat model Anda sudah memiliki fondasi yang sangat kokoh. Namun, untuk menghadapi lanskap digital 2026 dan seterusnya, berikut adalah tiga saran pengembangan strategis agar model tersebut tetap relevan: 1. Adopsi "Continuous Planning" (Agile Architecture): 2. Integrasi Pilar Artificial Intelligence Governance (AIG): 3. Penyelarasan dengan Keberlanjutan (Green IT): | AX10: =FALSE() -> FALSE | AY10: =TRUE() -> TRUE | AZ10: =AVERAGE(K10:O10) -> 4.2 | BG10: =IF(AZ10>=4,1,0) -> 1
A11: 46077.476 | B11: Andri Firmansyah | C11: Pria | D11: Akademisi (Guru, Dosen) | E11: 16.Pendidikan | F11: 0818731617 | G11: Tata Kelola TI/ IT Governance, Perencanaan Strategis TI, Audit & Manajemen TI, Infrastructure IT | I11: 11-15 Tahun | J11: COBIT, ITIL | K11: 5 | L11: 4 | M11: 4 | N11: 5 | O11: 4 | P11: 4 | Q11: 4 | R11: 4 | S11: 5 | T11: 5 | U11: 4 | V11: 4 | W11: 4 | X11: 4 | Y11: 4 | Z11: 3 | AA11: 3 | AB11: 3 | AC11: 3 | AD11: 3 | AF11: 4 | AG11: 4 | AH11: 4 | AI11: 4 | AJ11: 4 | AK11: 4 | AL11: 4 | AM11: 4 | AN11: 4 | AO11: 4 | AP11: 4 | AQ11: 4 | AT11: Sudah | AU11: Sudah lengkap | AV11: Dapat, karena komponen di framework sudah dapat mengakomodasi bisnis pendidikan | AW11: saat ini belum. | AX11: =FALSE() -> FALSE | AY11: =TRUE() -> TRUE | AZ11: =AVERAGE(K11:O11) -> 4.4 | BG11: =IF(AZ11>=4,1,0) -> 1
A12: 46077.512 | B12: Nurkholis | C12: Pria | D12: Konsultan IT | E12: 19.Aktivitas Jasa Lainnya | F12: 08123352506 | G12: Pengembang Aplikasi | I12: > 20 Tahun | J12: SPBE | K12: 4 | L12: 4 | M12: 3 | N12: 4 | O12: 4 | P12: 3 | Q12: 2 | R12: 3 | S12: 4 | T12: 4 | U12: 3 | V12: 4 | W12: 4 | X12: 4 | Y12: 4 | Z12: 3 | AA12: 3 | AB12: 3 | AC12: 4 | AD12: 4 | AF12: 4 | AG12: 5 | AH12: 4 | AI12: 5 | AJ12: 5 | AK12: 4 | AL12: 4 | AM12: 5 | AN12: 4 | AO12: 5 | AP12: 5 | AQ12: 4 | AT12: Sudah | AU12: Sudah terintegrasi semua | AV12: Iya, karena ini muaranya ke perbaikan tata kelola dan kinerja organisai | AW12: Studi kasus pada UMKM dan perusahaan kecll | AX12: =FALSE() -> FALSE | AY12: =TRUE() -> TRUE | AZ12: =AVERAGE(K12:O12) -> 3.8 | BG12: =IF(AZ12>=4,1,0) -> 0
A13: 46077.539 | B13: Christian | C13: Pria | D13: Konsultan IT | E13: 10.Informasi dan Komunikasi | G13: Tata Kelola TI/ IT Governance | I13: > 20 Tahun | J13: COBIT, ITIL, SPBE | K13: 5 | L13: 5 | M13: 4 | N13: 5 | O13: 5 | P13: 5 | Q13: 4 | R13: 5 | S13: 5 | T13: 4 | U13: 5 | V13: 5 | W13: 5 | X13: 5 | Y13: 5 | Z13: 4 | AA13: 4 | AB13: 4 | AC13: 4 | AD13: 4 | AF13: 5 | AG13: 5 | AH13: 5 | AI13: 5 | AJ13: 5 | AK13: 4 | AL13: 5 | AM13: 5 | AN13: 5 | AO13: 5 | AP13: 5 | AQ13: 4 | AT13: Ya , asalkan dijelaskan secara lengkap | AU13: Arsitektur, harus dapat mudah dibaca | AV13: Tidak, organisasi saya terlalu kecil | AW13: diberikan template, guide dan contoh | AX13: =FALSE() -> FALSE | AY13: =TRUE() -> TRUE | AZ13: =AVERAGE(K13:O13) -> 4.8 | BG13: =IF(AZ13>=4,1,0) -> 1
A14: 46077.545 | B14: Expert 3 | C14: Pria | D14: Konsultan IT | E14: 10.Informasi dan Komunikasi | G14: Tata Kelola TI/ IT Governance, Arsitektur Enterprise, Perencanaan Strategis TI, Audit & Manajemen TI | H14: Pakar perencanaan strategis TI | I14: 11-15 Tahun | J14: TOGAF, Ward & Peppard, COBIT, ITIL, SPBE | K14: 5 | L14: 5 | M14: 4 | N14: 5 | O14: 5 | P14: 5 | Q14: 4 | R14: 5 | S14: 4 | T14: 5 | U14: 5 | V14: 5 | W14: 5 | X14: 5 | Y14: 4 | Z14: 4 | AA14: 5 | AB14: 4 | AC14: 4 | AD14: 4 | AE14: 4 | AF14: 3 | AG14: 5 | AH14: 5 | AI14: 5 | AJ14: 5 | AK14: 4 | AL14: 3 | AM14: 5 | AN14: 5 | AO14: 5 | AP14: 5 | AQ14: 4 | AT14: Sudah | AV14: Dapat diterapkan, karena tingkat flexibilitasnya | AW14: Mungkin perlu dibandingkan juga dengan beberapa framework perencanaan strategis stau EA lainnya (cth. Anita Cassidy dll) | AX14: =TRUE() -> TRUE | AY14: =FALSE() -> FALSE | AZ14: =AVERAGE(K14:O14) -> 4.8 | BA14: =AVERAGE(P14:T14) -> 4.6 | BB14: =AVERAGE(U14:Y14) -> 4.8 | BC14: =AVERAGE(Z14:AD14) -> 4.2 | BD14: =AVERAGE(AE14:AI14) -> 4.4 | BE14: =AVERAGE(AJ14:AN14) -> 4.4 | BF14: =AVERAGE(AO14:AS14) -> 4.6666667 | BG14: =IF(AZ14>=4,1,0) -> 1 | BH14: =IF(BA14>=4,1,0) -> 1 | BI14: =IF(BB14>=4,1,0) -> 1 | BJ14: =IF(BC14>=4,1,0) -> 1 | BK14: =IF(BD14>=4,1,0) -> 1 | BL14: =IF(BE14>=4,1,0) -> 1 | BM14: =IF(BF14>=4,1,0) -> 1
A15: 46077.548 | B15: Expert 4 | C15: Pria | D15: Konsultan IT, Praktisi IT | E15: 10.Informasi dan Komunikasi, 13.Aktivitas Profesional, Ilmiah, dan Teknis, 19.Aktivitas Jasa Lainnya | G15: Arsitektur Enterprise, Audit & Manajemen TI, Pengembang Aplikasi, Infrastructure IT, Cybersecurity | H15: Pakar perencanaan strategis TI | I15: > 20 Tahun | J15: TOGAF, COBIT, ITIL, SPBE | K15: 4 | L15: 4 | M15: 3 | N15: 5 | O15: 4 | P15: 4 | Q15: 4 | R15: 4 | S15: 4 | T15: 4 | U15: 4 | V15: 3 | W15: 4 | X15: 4 | Y15: 4 | Z15: 5 | AA15: 4 | AB15: 4 | AC15: 4 | AD15: 4 | AE15: 4 | AF15: 5 | AG15: 4 | AH15: 4 | AI15: 4 | AJ15: 4 | AK15: 5 | AL15: 3 | AM15: 3 | AN15: 4 | AO15: 4 | AP15: 4 | AQ15: 5 | AT15: Cukup terintegrasi dengan baik | AU15: Tata Kelola dan Bisnis Proses | AV15: Iya , karena bisnis berbasis dengan keptuhan kerja pada struktur organisasi dan standar operasional prosedur pelayanan | AW15: Integrasi harus lebih luas mencakup semua aspek organisasi baik internal maupun external, hal ini terkait pertumbuhan dari beberapa teknologi IT semakin banyak dan mempunyai varian yang berbeda beda. | AX15: =TRUE() -> TRUE | AY15: =FALSE() -> FALSE | AZ15: =AVERAGE(K15:O15) -> 4 | BA15: =AVERAGE(P15:T15) -> 4 | BB15: =AVERAGE(U15:Y15) -> 3.8 | BC15: =AVERAGE(Z15:AD15) -> 4.2 | BD15: =AVERAGE(AE15:AI15) -> 4.2 | BE15: =AVERAGE(AJ15:AN15) -> 3.8 | BF15: =AVERAGE(AO15:AS15) -> 4.3333333 | BG15: =IF(AZ15>=4,1,0) -> 1 | BH15: =IF(BA15>=4,1,0) -> 1 | BI15: =IF(BB15>=4,1,0) -> 0 | BJ15: =IF(BC15>=4,1,0) -> 1 | BK15: =IF(BD15>=4,1,0) -> 1 | BL15: =IF(BE15>=4,1,0) -> 0 | BM15: =IF(BF15>=4,1,0) -> 1
A16: 46077.561 | B16: Expert 5 | C16: Pria | D16: Akademisi (Guru, Dosen), Konsultan IT, Praktisi IT | E16: 13.Aktivitas Profesional, Ilmiah, dan Teknis, 16.Pendidikan | G16: Arsitektur Enterprise, Audit & Manajemen TI, Pengembang Aplikasi, Cybersecurity, Keamanan Sistem Informasi | H16: Pakar enterprise architecture | I16: > 20 Tahun | J16: TOGAF, COBIT, SPBE | K16: 5 | L16: 5 | M16: 5 | N16: 5 | O16: 5 | P16: 5 | Q16: 5 | R16: 5 | S16: 5 | T16: 5 | U16: 5 | V16: 5 | W16: 5 | X16: 5 | Y16: 5 | Z16: 5 | AA16: 5 | AB16: 5 | AC16: 5 | AD16: 5 | AE16: 4 | AF16: 4 | AG16: 4 | AH16: 4 | AI16: 4 | AJ16: 4 | AK16: 4 | AL16: 4 | AM16: 4 | AN16: 3 | AO16: 4 | AP16: 4 | AQ16: 4 | AT16: Menurut saya sudah. | AU16: Integrasinya perlu dilakukan pengujian dan implementasi lebih lanjut. | AV16: Dapat. Karena framework ini mengintegrasikan framework (Ward & Prepart, Togaf dan Cobit 2019) yang sudah umum dan sudah menjadi standar framework yang selama ini telah diimplementasikan. | AW16: Saran tambahan dari saya, lebih ke arah implementasi di beberapa industri, agar dapat dilihat dan dapat dianalisa kesenjangan yang ada sehingga dari sini dapat dilakukan penyempurnaan framework. | AX16: =TRUE() -> TRUE | AY16: =FALSE() -> FALSE | AZ16: =AVERAGE(K16:O16) -> 5 | BA16: =AVERAGE(P16:T16) -> 5 | BB16: =AVERAGE(U16:Y16) -> 5 | BC16: =AVERAGE(Z16:AD16) -> 5 | BD16: =AVERAGE(AE16:AI16) -> 4 | BE16: =AVERAGE(AJ16:AN16) -> 3.8 | BF16: =AVERAGE(AO16:AS16) -> 4 | BG16: =IF(AZ16>=4,1,0) -> 1 | BH16: =IF(BA16>=4,1,0) -> 1 | BI16: =IF(BB16>=4,1,0) -> 1 | BJ16: =IF(BC16>=4,1,0) -> 1 | BK16: =IF(BD16>=4,1,0) -> 1 | BL16: =IF(BE16>=4,1,0) -> 0 | BM16: =IF(BF16>=4,1,0) -> 1
A17: 46077.595 | B17: Expert 6 | C17: Pria | D17: Konsultan IT, Praktisi IT | E17: 10.Informasi dan Komunikasi | G17: Tata Kelola TI/ IT Governance, Arsitektur Enterprise, Perencanaan Strategis TI, Pengembang Aplikasi, Infrastructure IT, Cybersecurity, IT Managed Services | H17: Pakar perencanaan strategis TI | I17: > 20 Tahun | J17: TOGAF, COBIT, ITIL, ITSM, NIST, ISO 27001 | K17: 5 | L17: 5 | M17: 5 | N17: 5 | O17: 5 | P17: 5 | Q17: 5 | R17: 5 | S17: 5 | T17: 5 | U17: 4 | V17: 4 | W17: 4 | X17: 5 | Y17: 4 | Z17: 2 | AA17: 2 | AB17: 3 | AC17: 3 | AD17: 4 | AE17: 4 | AF17: 4 | AG17: 4 | AH17: 5 | AI17: 4 | AJ17: 4 | AK17: 4 | AL17: 3 | AM17: 4 | AN17: 5 | AO17: 4 | AP17: 4 | AQ17: 4 | AT17: Iya | AU17: Tata Kelola | AV17: Belum bisa karena bisnis model berbeda | AW17: Di support oleh tools dan AI yang terintegrasi | AX17: =TRUE() -> TRUE | AY17: =FALSE() -> FALSE | AZ17: =AVERAGE(K17:O17) -> 5 | BA17: =AVERAGE(P17:T17) -> 5 | BB17: =AVERAGE(U17:Y17) -> 4.2 | BC17: =AVERAGE(Z17:AD17) -> 2.8 | BD17: =AVERAGE(AE17:AI17) -> 4.2 | BE17: =AVERAGE(AJ17:AN17) -> 4 | BF17: =AVERAGE(AO17:AS17) -> 4 | BG17: =IF(AZ17>=4,1,0) -> 1 | BH17: =IF(BA17>=4,1,0) -> 1 | BI17: =IF(BB17>=4,1,0) -> 1 | BJ17: =IF(BC17>=4,1,0) -> 0 | BK17: =IF(BD17>=4,1,0) -> 1 | BL17: =IF(BE17>=4,1,0) -> 1 | BM17: =IF(BF17>=4,1,0) -> 1
A18: 46077.602 | B18: Expert 7 | C18: Pria | D18: Praktisi IT | E18: 10.Informasi dan Komunikasi, 11.Aktivitas Keuangan dan Asuransi, | G18: Tata Kelola TI/ IT Governance, Arsitektur Enterprise, Perencanaan Strategis TI, Pengembang Aplikasi, Infrastructure IT, Cybersecurity | H18: Praktisi TI atau manajer TI | I18: > 20 Tahun | J18: TOGAF, Ward & Peppard, COBIT, ITIL, SPBE | K18: 5 | L18: 5 | M18: 5 | N18: 5 | O18: 5 | P18: 4 | Q18: 5 | R18: 4 | S18: 4 | T18: 5 | U18: 5 | V18: 5 | W18: 4 | X18: 5 | Y18: 4 | Z18: 4 | AA18: 4 | AB18: 4 | AC18: 4 | AD18: 4 | AE18: 4 | AF18: 5 | AG18: 5 | AH18: 5 | AI18: 5 | AJ18: 5 | AK18: 4 | AL18: 5 | AM18: 5 | AN18: 5 | AO18: 5 | AP18: 5 | AQ18: 4 | AX18: =TRUE() -> TRUE | AY18: =FALSE() -> FALSE | AZ18: =AVERAGE(K18:O18) -> 5 | BA18: =AVERAGE(P18:T18) -> 4.4 | BB18: =AVERAGE(U18:Y18) -> 4.6 | BC18: =AVERAGE(Z18:AD18) -> 4 | BD18: =AVERAGE(AE18:AI18) -> 4.8 | BE18: =AVERAGE(AJ18:AN18) -> 4.8 | BF18: =AVERAGE(AO18:AS18) -> 4.6666667 | BG18: =IF(AZ18>=4,1,0) -> 1 | BH18: =IF(BA18>=4,1,0) -> 1 | BI18: =IF(BB18>=4,1,0) -> 1 | BJ18: =IF(BC18>=4,1,0) -> 1 | BK18: =IF(BD18>=4,1,0) -> 1 | BL18: =IF(BE18>=4,1,0) -> 1 | BM18: =IF(BF18>=4,1,0) -> 1
A19: 46077.606 | B19: Expert 8 | C19: Pria | D19: Konsultan IT, Praktisi IT | E19: 21.Aktivitas Badan Internasional dan Badan Ekstra Internasional | G19: Tata Kelola TI/ IT Governance, Arsitektur Enterprise, Perencanaan Strategis TI, Audit & Manajemen TI, Pengembang Aplikasi, Infrastructure IT | H19: Pakar enterprise architecture | I19: > 20 Tahun | J19: TOGAF, COBIT, ITIL, SPBE, Zachman Framework, Moscow Framework, dll | K19: 5 | L19: 4 | M19: 4 | N19: 5 | O19: 4 | P19: 4 | Q19: 4 | R19: 4 | S19: 4 | T19: 4 | U19: 5 | V19: 5 | W19: 4 | X19: 5 | Y19: 5 | Z19: 4 | AA19: 5 | AB19: 4 | AC19: 5 | AD19: 5 | AE19: 4 | AF19: 5 | AG19: 5 | AH19: 5 | AI19: 5 | AJ19: 5 | AK19: 5 | AL19: 5 | AM19: 5 | AN19: 5 | AO19: 5 | AP19: 5 | AQ19: 5 | AT19: Sudah, walaupun masih ada komponen lain yang berhubungan dengan visi dan misi sebuah institusi | AU19: Yang perlu di sempurnakan dalam penerapan strategi dalam satu institusi adalah change management | AV19: Tentu ada, karena ini sebagai kompas dan guideline dalam menempuh setiap pentahapan pekerjaan | AW19: Setiap framework memiliki kelebihannya masing-masing harus ada sebuah jembatan yang diperlukan dalam perencanaan strategis tidak hanya di dibidang TI tetapi juga berkolerasi dalam strategis bisnis | AX19: =TRUE() -> TRUE | AY19: =FALSE() -> FALSE | AZ19: =AVERAGE(K19:O19) -> 4.4 | BA19: =AVERAGE(P19:T19) -> 4 | BB19: =AVERAGE(U19:Y19) -> 4.8 | BC19: =AVERAGE(Z19:AD19) -> 4.6 | BD19: =AVERAGE(AE19:AI19) -> 4.8 | BE19: =AVERAGE(AJ19:AN19) -> 5 | BF19: =AVERAGE(AO19:AS19) -> 5 | BG19: =IF(AZ19>=4,1,0) -> 1 | BH19: =IF(BA19>=4,1,0) -> 1 | BI19: =IF(BB19>=4,1,0) -> 1 | BJ19: =IF(BC19>=4,1,0) -> 1 | BK19: =IF(BD19>=4,1,0) -> 1 | BL19: =IF(BE19>=4,1,0) -> 1 | BM19: =IF(BF19>=4,1,0) -> 1
A20: 46077.613 | B20: Expert 9 | C20: Pria | D20: Akademisi (Guru, Dosen) | E20: 3.Industri Pengolahan, 7.Perdagangan Besar & Eceran; Reparasi dan Perawatan Mobil dan Sepeda Motor, 9.Penyediaan Akomodasi dan Makanan & Minuman | G20: Tata Kelola TI/ IT Governance, Arsitektur Enterprise, Perencanaan Strategis TI, Audit & Manajemen TI, Pengembang Aplikasi, Cybersecurity | H20: Akademisi sistem informasi | I20: 16-20 Tahun | J20: TOGAF, COBIT, ITIL, SPBE | K20: 5 | L20: 5 | M20: 5 | N20: 5 | O20: 5 | P20: 5 | Q20: 5 | R20: 5 | S20: 5 | T20: 5 | U20: 5 | V20: 5 | W20: 5 | X20: 5 | Y20: 5 | Z20: 5 | AA20: 5 | AB20: 5 | AC20: 5 | AD20: 5 | AE20: 4 | AF20: 4 | AG20: 4 | AH20: 4 | AI20: 4 | AJ20: 4 | AK20: 4 | AL20: 4 | AM20: 4 | AN20: 4 | AO20: 4 | AP20: 4 | AQ20: 4 | AT20: Ya | AU20: Keamanan Informasi (Cybersecurity) | AV20: Dapat diterapkan | AW20: Penyelarasan dengan AI (Artificial | AX20: =TRUE() -> TRUE | AY20: =FALSE() -> FALSE | AZ20: =AVERAGE(K20:O20) -> 5 | BA20: =AVERAGE(P20:T20) -> 5 | BB20: =AVERAGE(U20:Y20) -> 5 | BC20: =AVERAGE(Z20:AD20) -> 5 | BD20: =AVERAGE(AE20:AI20) -> 4 | BE20: =AVERAGE(AJ20:AN20) -> 4 | BF20: =AVERAGE(AO20:AS20) -> 4 | BG20: =IF(AZ20>=4,1,0) -> 1 | BH20: =IF(BA20>=4,1,0) -> 1 | BI20: =IF(BB20>=4,1,0) -> 1 | BJ20: =IF(BC20>=4,1,0) -> 1 | BK20: =IF(BD20>=4,1,0) -> 1 | BL20: =IF(BE20>=4,1,0) -> 1 | BM20: =IF(BF20>=4,1,0) -> 1
A21: 46077.709 | B21: Expert 10 | C21: Pria | D21: Akademisi (Guru, Dosen) | E21: 16.Pendidikan | G21: Perencanaan Strategis TI, Cybersecurity | H21: Praktisi TI atau manajer TI | I21: > 20 Tahun | J21: TOGAF, Ward & Peppard, COBIT | K21: 5 | L21: 5 | M21: 5 | N21: 5 | O21: 5 | P21: 5 | Q21: 4 | R21: 5 | S21: 5 | T21: 5 | U21: 5 | V21: 5 | W21: 5 | X21: 5 | Y21: 5 | Z21: 3 | AA21: 5 | AB21: 5 | AC21: 5 | AD21: 5 | AE21: 4 | AF21: 4 | AG21: 4 | AH21: 5 | AI21: 5 | AJ21: 5 | AK21: 4 | AL21: 4 | AM21: 4 | AN21: 5 | AO21: 5 | AP21: 5 | AQ21: 5 | AR21: 5 | AS21: 5 | AT21: Ya | AU21: Tata kelola TI | AV21: Ya, karena sesuai dengan kebutuhan organisasi saya. | AW21: Sustainability integration | AX21: =TRUE() -> TRUE | AY21: =FALSE() -> FALSE | AZ21: =AVERAGE(K21:O21) -> 5 | BA21: =AVERAGE(P21:T21) -> 4.8 | BB21: =AVERAGE(U21:Y21) -> 5 | BC21: =AVERAGE(Z21:AD21) -> 4.6 | BD21: =AVERAGE(AE21:AI21) -> 4.4 | BE21: =AVERAGE(AJ21:AN21) -> 4.4 | BF21: =AVERAGE(AO21:AS21) -> 5 | BG21: =IF(AZ21>=4,1,0) -> 1 | BH21: =IF(BA21>=4,1,0) -> 1 | BI21: =IF(BB21>=4,1,0) -> 1 | BJ21: =IF(BC21>=4,1,0) -> 1 | BK21: =IF(BD21>=4,1,0) -> 1 | BL21: =IF(BE21>=4,1,0) -> 1 | BM21: =IF(BF21>=4,1,0) -> 1
A22: 46078.202 | B22: Expert 11 | C22: Pria | D22: Akademisi (Guru, Dosen) | E22: 10.Informasi dan Komunikasi, 16.Pendidikan | G22: Tata Kelola TI/ IT Governance, Arsitektur Enterprise, Perencanaan Strategis TI | H22: Pakar enterprise architecture | I22: > 20 Tahun | J22: TOGAF, COBIT, SPBE | K22: 4 | L22: 4 | M22: 4 | N22: 4 | O22: 4 | P22: 4 | Q22: 4 | R22: 4 | S22: 4 | T22: 4 | U22: 2 | V22: 4 | W22: 4 | X22: 4 | Y22: 4 | Z22: 4 | AA22: 5 | AB22: 4 | AC22: 4 | AD22: 4 | AE22: 5 | AF22: 5 | AG22: 5 | AH22: 5 | AI22: 5 | AJ22: 5 | AK22: 4 | AL22: 5 | AM22: 5 | AN22: 5 | AO22: 5 | AP22: 5 | AQ22: 5 | AR22: 5 | AS22: 5 | AT22: ya | AU22: pemetaan arsitektur as-is yang relevan | AV22: pada dasarnya penerapan framework ini bergantung pada pemahaman para pimpinan (leader) | AW22: pemetaan arsitektur as is yang transparan sehingga dapat menghasilkan perencanaan yang lebih akurat dalam pelaksanaan | AX22: =TRUE() -> TRUE | AY22: =FALSE() -> FALSE | AZ22: =AVERAGE(K22:O22) -> 4 | BA22: =AVERAGE(P22:T22) -> 4 | BB22: =AVERAGE(U22:Y22) -> 3.6 | BC22: =AVERAGE(Z22:AD22) -> 4.2 | BD22: =AVERAGE(AE22:AI22) -> 5 | BE22: =AVERAGE(AJ22:AN22) -> 4.8 | BF22: =AVERAGE(AO22:AS22) -> 5 | BG22: =IF(AZ22>=4,1,0) -> 1 | BH22: =IF(BA22>=4,1,0) -> 1 | BI22: =IF(BB22>=4,1,0) -> 0 | BJ22: =IF(BC22>=4,1,0) -> 1 | BK22: =IF(BD22>=4,1,0) -> 1 | BL22: =IF(BE22>=4,1,0) -> 1 | BM22: =IF(BF22>=4,1,0) -> 1
A23: 46078.314 | B23: Expert 12 | C23: Pria | D23: Praktisi IT | E23: 2. Pertambangan dan Penggalian | G23: Perencanaan Strategis TI, Audit & Manajemen TI, Pengembang Aplikasi | H23: Praktisi TI atau manajer TI | I23: 11-15 Tahun | J23: TOGAF, COBIT, ITIL | K23: 4 | L23: 4 | M23: 4 | N23: 4 | O23: 4 | P23: 4 | Q23: 4 | R23: 4 | S23: 4 | T23: 5 | U23: 5 | V23: 5 | W23: 5 | X23: 4 | Y23: 4 | Z23: 4 | AA23: 4 | AB23: 4 | AC23: 4 | AD23: 4 | AE23: 4 | AF23: 4 | AG23: 4 | AH23: 4 | AI23: 4 | AJ23: 4 | AK23: 4 | AL23: 4 | AM23: 4 | AN23: 3 | AO23: 4 | AP23: 4 | AQ23: 4 | AR23: 4 | AS23: 4 | AT23: Ya, model tersebut pada prinsipnya sudah menggambarkan hubungan yang logis dan berurutan. Strategi TI menjadi arah (why), arsitektur TI menjadi desain implementatif (what & how), dan tata kelola TI memastikan pengendalian, kepatuhan, serta pencapaian nilai (control & assurance). Jika dirancang dengan baik, ketiganya membentuk siklus yang saling menguatkan dan terintegrasi. | AU23: Keterkaitan KPI dan value realization, agar lebih terukur kontribusinya terhadap kinerja bisnis. Manajemen risiko dan keamanan informasi, agar terintegrasi eksplisit dalam arsitektur dan governance. Mekanisme feedback loop, untuk memastikan evaluasi berkala dan continuous improvement. Change management & people aspect, karena transformasi TI sangat bergantung pada kesiapan organisasi. | AV23: Ya, dapat diterapkan. Dalam konteks organisasi yang kompleks dan teregulasi, integrasi antara strategi, arsitektur, dan tata kelola sangat penting untuk menjaga alignment dengan tujuan korporasi, memastikan kepatuhan regulasi, serta mengoptimalkan investasi TI. Model ini juga relevan untuk meningkatkan maturity tata kelola TI secara bertahap dan terstruktur. | AW23: Mengintegrasikan pendekatan berbasis value (value-based IT management). Memasukkan elemen digital capability dan data governance secara eksplisit. Menambahkan indikator maturity level sebagai alat ukur perkembangan. Menyesuaikan model agar adaptif terhadap dinamika teknologi seperti AI, cloud, dan cybersecurity risk. | AX23: =TRUE() -> TRUE | AY23: =FALSE() -> FALSE | AZ23: =AVERAGE(K23:O23) -> 4 | BA23: =AVERAGE(P23:T23) -> 4.2 | BB23: =AVERAGE(U23:Y23) -> 4.6 | BC23: =AVERAGE(Z23:AD23) -> 4 | BD23: =AVERAGE(AE23:AI23) -> 4 | BE23: =AVERAGE(AJ23:AN23) -> 3.8 | BF23: =AVERAGE(AO23:AS23) -> 4 | BG23: =IF(AZ23>=4,1,0) -> 1 | BH23: =IF(BA23>=4,1,0) -> 1 | BI23: =IF(BB23>=4,1,0) -> 1 | BJ23: =IF(BC23>=4,1,0) -> 1 | BK23: =IF(BD23>=4,1,0) -> 1 | BL23: =IF(BE23>=4,1,0) -> 0 | BM23: =IF(BF23>=4,1,0) -> 1
A24: 46078.327 | B24: Bayu Wirayuda | C24: Pria | D24: Praktisi IT | E24: 8.Pengangkutan dan Pergudangan, 19.Aktivitas Jasa Lainnya | F24: 085888173222 | G24: Infrastructure IT, Cybersecurity | I24: 5-10 Tahun | J24: COBIT, ITIL | K24: 5 | L24: 5 | M24: 4 | N24: 5 | O24: 5 | P24: 4 | Q24: 4 | R24: 4 | S24: 5 | T24: 4 | U24: 5 | V24: 5 | W24: 5 | X24: 4 | Y24: 5 | Z24: 5 | AA24: 5 | AB24: 4 | AC24: 5 | AD24: 5 | AF24: 3 | AG24: 4 | AH24: 5 | AI24: 4 | AJ24: 4 | AK24: 4 | AL24: 5 | AM24: 5 | AN24: 5 | AO24: 5 | AP24: 5 | AQ24: 5 | AR24: 5 | AS24: 5 | AT24: Menurut pandangan saya, model Integrasi Perencanaan Strategis TI telah mampu merepresentasikan keterkaitan yang logis antara strategi, arsitektur, dan tata kelola TI, selama model tersebut dirancang secara bertahap, terstruktur, serta memiliki keterhubungan yang jelas baik secara vertikal (top-down) maupun secara horizontal melalui penyelarasan lintas fungsi. | AU24: Apabila meninjau model Integrasi Perencanaan Strategis TI secara umum, terdapat beberapa komponen yang umumnya masih perlu diperbaiki atau disempurnakan agar keterkaitan antara strategi, arsitektur, dan tata kelola TI dapat berjalan secara lebih optimal dan efektif. | AV24: Pada dasarnya, framework Integrasi Perencanaan Strategis TI dapat diimplementasikan dalam lingkungan organisasi, khususnya pada organisasi yang memiliki proses bisnis yang kompleks, beragam aplikasi, serta tuntutan tata kelola TI yang kuat dan terstruktur. Alasannya : 1. Mendukung Alignment Bisnis dan TI 2. Memberikan Struktur yang Sistematis 3. Meningkatkan Pengendalian Risiko dan Investasi 4. Cocok untuk Organisasi yang Sedang Transformasi Digital | AW24: saran tambahan untuk pengembangan model Integrasi Perencanaan Strategis TI di masa mendatang agar lebih adaptif, terukur, dan relevan dengan dinamika bisnis: 1. Integrasi Digital Strategy dan Business Agility 2. Penguatan Data-Driven Governance 3. Integrasi Manajemen Risiko Siber 4. Penyesuaian dengan Arsitektur Hybrid (Cloud & On-Premise) 5. Penguatan Change Management & People Aspect 6. Continuous Improvement Framework | AX24: =FALSE() -> FALSE | AY24: =TRUE() -> TRUE | AZ24: =AVERAGE(K24:O24) -> 4.8 | BG24: =IF(AZ24>=4,1,0) -> 1
A25: 46078.364 | B25: Shofwan Hanief | C25: Pria | D25: Akademisi (Guru, Dosen) | E25: 16.Pendidikan | F25: 081239555799 | G25: Audit & Manajemen TI | I25: 5-10 Tahun | J25: COBIT, ITIL, SPBE | K25: 3 | L25: 4 | M25: 4 | N25: 4 | O25: 4 | P25: 4 | Q25: 4 | R25: 4 | S25: 5 | T25: 5 | U25: 4 | V25: 4 | W25: 5 | X25: 4 | Y25: 5 | Z25: 3 | AA25: 4 | AB25: 4 | AC25: 4 | AD25: 4 | AF25: 5 | AG25: 5 | AH25: 5 | AI25: 5 | AJ25: 5 | AK25: 4 | AL25: 4 | AM25: 4 | AN25: 4 | AO25: 4 | AP25: 4 | AQ25: 4 | AR25: 4 | AS25: 4 | AT25: Sudah dapat memotret | AU25: Service quality | AV25: Dapat, karena flexible disesuaikan dengan kebutuhan dan tujuan organisasi dalam mengelola TI | AW25: Berbasis komputerisasi agar proses tata kelola dan evaluasi dapat terlihat perjalanannya dari tahun ke tahun | AX25: =FALSE() -> FALSE | AY25: =TRUE() -> TRUE | AZ25: =AVERAGE(K25:O25) -> 3.8 | BG25: =IF(AZ25>=4,1,0) -> 0
A26: 46078.408 | B26: Expert 13 | C26: Pria | D26: Konsultan IT | E26: 10.Informasi dan Komunikasi | G26: Tata Kelola TI/ IT Governance, Audit & Manajemen TI, Pengembang Aplikasi | H26: Pakar perencanaan strategis TI | I26: < 5 Tahun | J26: TOGAF, COBIT, ITIL, SPBE | K26: 5 | L26: 5 | M26: 5 | N26: 5 | O26: 5 | P26: 4 | Q26: 4 | R26: 4 | S26: 4 | T26: 4 | U26: 4 | V26: 4 | W26: 4 | X26: 4 | Y26: 4 | Z26: 3 | AA26: 4 | AB26: 5 | AC26: 4 | AD26: 4 | AE26: 4 | AF26: 5 | AG26: 5 | AH26: 5 | AI26: 5 | AJ26: 5 | AK26: 5 | AL26: 4 | AM26: 4 | AN26: 5 | AO26: 5 | AP26: 5 | AQ26: 5 | AR26: 5 | AS26: 5 | AT26: Model integrasi sudah menggambarkan hubungan logis yang jelas antara strategi, arsitektur, dan tata kelola TI, dimana strategi TI (Ward & Peppard) menjadi dasar dalam perancangan arsitektur (TOGAF), dan selanjutnya dikendalikan serta dimonitor melalui tata kelola TI (COBIT 2019). Hubungan ini menunjukkan alur yang terstruktur dari perencanaan hingga implementasi dan pengendalian. | AU26: Komponen yang perlu disempurnakan adalah: Mekanisme integrasi antar framework (mapping yang lebih detail antar artefak) Penyesuaian terhadap tingkat kematangan organisasi (maturity level) Penyederhanaan implementasi agar lebih praktis dan tidak terlalu kompleks Penambahan aspek agile/adaptability untuk mendukung perubahan bisnis yang cepat | AV26: Framework ini dapat diterapkan di organisasi karena mampu mengintegrasikan aspek strategi, arsitektur, dan tata kelola TI secara menyeluruh. Selain itu, framework ini mendukung kebutuhan organisasi dalam hal alignment bisnis dan TI, pengelolaan risiko, serta penyusunan roadmap TI yang terstruktur. Namun, implementasinya perlu disesuaikan dengan tingkat kematangan dan kompleksitas organisasi. | AW26: Saran pengembangan ke depan: Menambahkan panduan implementasi praktis (guideline step-by-step) Mengintegrasikan pendekatan agile dan DevOps untuk meningkatkan adaptabilitas Menyediakan template artefak (roadmap, blueprint, KPI, risk register) Menyesuaikan model dengan berbagai level organisasi (kecil, menengah, besar) Mengintegrasikan dengan standar lain seperti ISO 27001 untuk penguatan aspek keamanan | AX26: =TRUE() -> TRUE | AY26: =FALSE() -> FALSE | AZ26: =AVERAGE(K26:O26) -> 5 | BA26: =AVERAGE(P26:T26) -> 4 | BB26: =AVERAGE(U26:Y26) -> 4 | BC26: =AVERAGE(Z26:AD26) -> 4 | BD26: =AVERAGE(AE26:AI26) -> 4.8 | BE26: =AVERAGE(AJ26:AN26) -> 4.6 | BF26: =AVERAGE(AO26:AS26) -> 5 | BG26: =IF(AZ26>=4,1,0) -> 1 | BH26: =IF(BA26>=4,1,0) -> 1 | BI26: =IF(BB26>=4,1,0) -> 1 | BJ26: =IF(BC26>=4,1,0) -> 1 | BK26: =IF(BD26>=4,1,0) -> 1 | BL26: =IF(BE26>=4,1,0) -> 1 | BM26: =IF(BF26>=4,1,0) -> 1
A27: 46078.44 | B27: Expert 14 | C27: Pria | D27: Konsultan IT | E27: 10.Informasi dan Komunikasi | G27: Tata Kelola TI/ IT Governance, Perencanaan Strategis TI | H27: Pakar enterprise architecture | I27: > 20 Tahun | J27: TOGAF, COBIT, ITIL | K27: 5 | L27: 5 | M27: 5 | N27: 5 | O27: 5 | P27: 5 | Q27: 4 | R27: 5 | S27: 5 | T27: 5 | U27: 5 | V27: 5 | W27: 5 | X27: 5 | Y27: 5 | Z27: 5 | AA27: 5 | AB27: 5 | AC27: 5 | AD27: 5 | AE27: 4 | AF27: 4 | AG27: 4 | AH27: 4 | AI27: 4 | AJ27: 4 | AK27: 4 | AL27: 4 | AM27: 4 | AN27: 4 | AO27: 4 | AP27: 4 | AQ27: 4 | AR27: 4 | AS27: 5 | AT27: Scara konseptual, model integrasi strategi-arsitektur-tata kelola sdh logis jk mengikuti alur : strategi bisnis & SI/TI (dari Ward n Peppard) -> penerjemahan ke enterprise architectur (togaf) -> pengendalian evaluasi kinerja (cobit). Rantai ini scara teori sdh tepat dan saling melengkapi. Nah. Karena masih highlevel, model cenderung linear…idealnya di+ mekanisme feedback dari governance (monitoring , evaluation) kembali ke level strategi agar lbh adaptif n dinamis | AU27: Komponen mekanisme translasi strategi ke arsitektur, agar tdk hanya konseptual tp jelas bagaimana portofolio strategis diterjemahkan menjd roadmap araitektur. Lalu perlu jg di+ aspek value realization dan feedback loop kinerja (cobit mea) ke strategic layer jd modelnya tidak ganya alignment-oriented tp outcome dan value driven | AV27: Bisa donk, karena menbantu menjaga alignment bisnis TI, konsisten arsitektur dan akuntabilitas serta kesiapan audit. Namun hati2 implementasinya harus disesuaikan dgn skala dan dinamika perusahaan. | AW27: Kedepan, modelnya perlu memasukkan perspektif transformasi digital (maturity digital n innovation governance). Juga perlu ditekankan alignment yg bersifat dinamis, lalu masukkan jg dimensi leadership, culture. | AX27: =TRUE() -> TRUE | AY27: =FALSE() -> FALSE | AZ27: =AVERAGE(K27:O27) -> 5 | BA27: =AVERAGE(P27:T27) -> 4.8 | BB27: =AVERAGE(U27:Y27) -> 5 | BC27: =AVERAGE(Z27:AD27) -> 5 | BD27: =AVERAGE(AE27:AI27) -> 4 | BE27: =AVERAGE(AJ27:AN27) -> 4 | BF27: =AVERAGE(AO27:AS27) -> 4.2 | BG27: =IF(AZ27>=4,1,0) -> 1 | BH27: =IF(BA27>=4,1,0) -> 1 | BI27: =IF(BB27>=4,1,0) -> 1 | BJ27: =IF(BC27>=4,1,0) -> 1 | BK27: =IF(BD27>=4,1,0) -> 1 | BL27: =IF(BE27>=4,1,0) -> 1 | BM27: =IF(BF27>=4,1,0) -> 1
A28: 46078.914 | B28: Expert 15 | C28: Pria | D28: Konsultan IT | E28: 10.Informasi dan Komunikasi | G28: Tata Kelola TI/ IT Governance, Arsitektur Enterprise | H28: Pakar enterprise architecture | I28: > 20 Tahun | J28: TOGAF, Ward & Peppard, COBIT, ITIL, SPBE, FEAF, ZACHMAN dll | K28: 5 | L28: 5 | M28: 5 | N28: 3 | O28: 4 | P28: 4 | Q28: 4 | R28: 4 | S28: 4 | T28: 4 | U28: 5 | V28: 5 | W28: 5 | X28: 5 | Y28: 5 | Z28: 5 | AA28: 5 | AB28: 5 | AC28: 5 | AD28: 5 | AE28: 5 | AF28: 4 | AG28: 4 | AH28: 5 | AI28: 5 | AJ28: 5 | AK28: 4 | AL28: 4 | AM28: 4 | AN28: 5 | AO28: 5 | AP28: 5 | AQ28: 5 | AR28: 5 | AS28: 5 | AT28: sudah pasti | AU28: tidak ada | AV28: dapat - masing-masing memiliki kelebihan dan kelemahan masing-masing | AW28: ----- | AX28: =TRUE() -> TRUE | AY28: =FALSE() -> FALSE | AZ28: =AVERAGE(K28:O28) -> 4.4 | BA28: =AVERAGE(P28:T28) -> 4 | BB28: =AVERAGE(U28:Y28) -> 5 | BC28: =AVERAGE(Z28:AD28) -> 5 | BD28: =AVERAGE(AE28:AI28) -> 4.6 | BE28: =AVERAGE(AJ28:AN28) -> 4.4 | BF28: =AVERAGE(AO28:AS28) -> 5 | BG28: =IF(AZ28>=4,1,0) -> 1 | BH28: =IF(BA28>=4,1,0) -> 1 | BI28: =IF(BB28>=4,1,0) -> 1 | BJ28: =IF(BC28>=4,1,0) -> 1 | BK28: =IF(BD28>=4,1,0) -> 1 | BL28: =IF(BE28>=4,1,0) -> 1 | BM28: =IF(BF28>=4,1,0) -> 1
A29: 46079.55 | B29: John Saimara | C29: Pria | D29: Praktisi IT | E29: 7.Perdagangan Besar & Eceran; Reparasi dan Perawatan Mobil dan Sepeda Motor | F29: 0811171135 | G29: Perencanaan Strategis TI | I29: > 20 Tahun | J29: COBIT | K29: 4 | L29: 4 | M29: 3 | N29: 3 | O29: 3 | P29: 3 | Q29: 3 | R29: 3 | S29: 3 | T29: 3 | U29: 3 | V29: 3 | W29: 3 | X29: 4 | Y29: 3 | Z29: 3 | AA29: 3 | AB29: 3 | AC29: 2 | AD29: 3 | AF29: 5 | AG29: 5 | AH29: 5 | AI29: 5 | AJ29: 5 | AK29: 4 | AL29: 5 | AM29: 5 | AN29: 5 | AO29: 5 | AP29: 5 | AS29: 4 | AT29: Ya, tapi memang perlu pemahaman yg lebih mendalam dahulu spy bisa melihat benang merahnya | AU29: Sudah baik, hanya pemahaman kita atas dasar teori tsb yg membuat kita kurang memahami konektivitasnya. Pengalaman di dunia IT sangat mempengaruhi implementasinya | AV29: Bisa saja, fokus pada solusi, fungsi dan kesesuaian dengan kondisi diskusi perusahaan. IT menyediakan banyak alternatif teknologi dan tools spy strategi IT bisa diimplementasikan. | AW29: Implementasinya tidak mudah tapi bukan berarti tidak bisa dijalankan. | AX29: =FALSE() -> FALSE | AY29: =TRUE() -> TRUE | AZ29: =AVERAGE(K29:O29) -> 3.4 | BG29: =IF(AZ29>=4,1,0) -> 0
A30: 46079.737 | B30: Expert 16 | C30: Pria | D30: Konsultan IT | E30: 10.Informasi dan Komunikasi | G30: Tata Kelola TI/ IT Governance, Perencanaan Strategis TI, Audit & Manajemen TI | H30: Pakar perencanaan strategis TI | I30: > 20 Tahun | J30: TOGAF, COBIT, ITIL | K30: 5 | L30: 5 | M30: 5 | N30: 5 | O30: 5 | P30: 4 | Q30: 4 | R30: 5 | S30: 4 | T30: 5 | U30: 5 | V30: 5 | W30: 4 | X30: 4 | Y30: 4 | Z30: 4 | AA30: 4 | AB30: 4 | AC30: 4 | AD30: 4 | AE30: 4 | AF30: 4 | AG30: 4 | AH30: 4 | AI30: 4 | AJ30: 4 | AK30: 4 | AL30: 4 | AM30: 4 | AN30: 4 | AO30: 4 | AP30: 4 | AQ30: 4 | AR30: 4 | AS30: 5 | AT30: perlu dikombinasikan dengan kerangka kerja lain. | AU30: sisi implementasi Ward & Peppard dengan menambahkan dimensi arsitektur teknis dan kontrol tata kelola | AV30: bisa karena keselarasan antara misi strategis dan investasi sesuai kondisi BUMN dan Bank | AW30: menciptakan model Perencanaan Strategis TI (PSTI) yang lebih tangguh dan relevan bagi organisasi modern (terutama Bank dan BUMN) | AX30: =TRUE() -> TRUE | AY30: =FALSE() -> FALSE | AZ30: =AVERAGE(K30:O30) -> 5 | BA30: =AVERAGE(P30:T30) -> 4.4 | BB30: =AVERAGE(U30:Y30) -> 4.4 | BC30: =AVERAGE(Z30:AD30) -> 4 | BD30: =AVERAGE(AE30:AI30) -> 4 | BE30: =AVERAGE(AJ30:AN30) -> 4 | BF30: =AVERAGE(AO30:AS30) -> 4.2 | BG30: =IF(AZ30>=4,1,0) -> 1 | BH30: =IF(BA30>=4,1,0) -> 1 | BI30: =IF(BB30>=4,1,0) -> 1 | BJ30: =IF(BC30>=4,1,0) -> 1 | BK30: =IF(BD30>=4,1,0) -> 1 | BL30: =IF(BE30>=4,1,0) -> 1 | BM30: =IF(BF30>=4,1,0) -> 1
A31: 46081.161 | B31: Expert 17 | C31: Pria | D31: Konsultan IT | E31: 13.Aktivitas Profesional, Ilmiah, dan Teknis | G31: Tata Kelola TI/ IT Governance, Arsitektur Enterprise, Perencanaan Strategis TI, Audit & Manajemen TI | H31: Pakar tata kelola TI atau COBIT | I31: 16-20 Tahun | J31: TOGAF, Ward & Peppard, COBIT, ITIL, SPBE, ISO 20000, ISO 27001, ISO 27701, DAMA DMBOK | K31: 5 | L31: 5 | M31: 3 | N31: 5 | O31: 5 | P31: 4 | Q31: 4 | R31: 5 | S31: 5 | T31: 5 | U31: 5 | V31: 5 | W31: 5 | X31: 5 | Y31: 5 | Z31: 4 | AA31: 4 | AB31: 5 | AC31: 5 | AD31: 5 | AE31: 4 | AF31: 4 | AG31: 4 | AH31: 5 | AI31: 5 | AJ31: 5 | AK31: 4 | AL31: 4 | AM31: 5 | AN31: 5 | AO31: 5 | AP31: 4 | AQ31: 5 | AR31: 5 | AS31: 4 | AT31: Ya | AV31: Ya | AW31: ditambahkan dengan NIST dan CIS agar lebih adaptif dalam kesiapan cyber security defense, khususnya dalam penerapan digitalisasi | AX31: =TRUE() -> TRUE | AY31: =FALSE() -> FALSE | AZ31: =AVERAGE(K31:O31) -> 4.6 | BA31: =AVERAGE(P31:T31) -> 4.6 | BB31: =AVERAGE(U31:Y31) -> 5 | BC31: =AVERAGE(Z31:AD31) -> 4.6 | BD31: =AVERAGE(AE31:AI31) -> 4.4 | BE31: =AVERAGE(AJ31:AN31) -> 4.6 | BF31: =AVERAGE(AO31:AS31) -> 4.6 | BG31: =IF(AZ31>=4,1,0) -> 1 | BH31: =IF(BA31>=4,1,0) -> 1 | BI31: =IF(BB31>=4,1,0) -> 1 | BJ31: =IF(BC31>=4,1,0) -> 1 | BK31: =IF(BD31>=4,1,0) -> 1 | BL31: =IF(BE31>=4,1,0) -> 1 | BM31: =IF(BF31>=4,1,0) -> 1
A32: 46081.171 | B32: Expert 1 8 | C32: Pria | D32: Konsultan IT | E32: 21.Aktivitas Badan Internasional dan Badan Ekstra Internasional | G32: Tata Kelola TI/ IT Governance | H32: Praktisi TI atau manajer TI | I32: 11-15 Tahun | J32: Ward & Peppard, COBIT, ITIL, SPBE | K32: 5 | L32: 5 | M32: 5 | N32: 5 | O32: 5 | P32: 5 | Q32: 5 | R32: 5 | S32: 5 | T32: 5 | U32: 5 | V32: 5 | W32: 5 | X32: 5 | Y32: 5 | Z32: 5 | AA32: 5 | AB32: 5 | AC32: 5 | AD32: 5 | AE32: 4 | AF32: 5 | AG32: 5 | AH32: 5 | AI32: 5 | AJ32: 5 | AK32: 5 | AL32: 5 | AM32: 5 | AN32: 5 | AO32: 5 | AP32: 4 | AQ32: 5 | AR32: 5 | AS32: 5 | AT32: Menurut saya, model Integrasi Perencanaan Strategis TI pada dasarnya sudah menggambarkan hubungan yang logis antara strategi, arsitektur, dan tata kelola TI. Strategi berperan sebagai arah dan tujuan organisasi, arsitektur TI menerjemahkan strategi tersebut ke dalam desain sistem, aplikasi, dan infrastruktur, sedangkan tata kelola TI memastikan bahwa implementasi berjalan sesuai kebijakan, standar, serta prinsip akuntabilitas. Jika ketiganya terhubung secara sistematis, maka akan tercipta keselarasan (alignment) antara tujuan bisnis dan pemanfaatan TI. | AU32: 1. Mekanisme evaluasi dan pengukuran kinerja (KPI TI) agar dampak strategi TI terhadap kinerja organisasi dapat diukur secara lebih objektif. 2. Manajemen risiko TI, terutama terkait keamanan informasi dan keberlanjutan layanan (business continuity). 3. Integrasi komunikasi antar unit bisnis dan TI, agar perencanaan tidak berjalan secara silo. 4. Fleksibilitas arsitektur, sehingga mampu beradaptasi dengan perubahan teknologi dan kebutuhan bisnis yang dinamis. | AV32: Framework ini pada prinsipnya dapat diterapkan, karena membantu menyelaraskan perencanaan TI dengan strategi organisasi secara menyeluruh. Dengan adanya integrasi antara strategi, arsitektur, dan tata kelola, organisasi dapat mengurangi pemborosan investasi TI, meningkatkan efisiensi operasional, serta memastikan bahwa setiap inisiatif TI benar-benar mendukung pencapaian tujuan strategis. Namun, keberhasilan penerapan sangat bergantung pada komitmen manajemen dan kesiapan sumber daya. | AW32: 1. Menambahkan pendekatan berbasis agile atau adaptive planning agar lebih responsif terhadap perubahan. 2. Mengintegrasikan aspek transformasi digital dan inovasi sebagai bagian eksplisit dalam model. 3. Memperkuat aspek manajemen perubahan (change management) untuk mendukung implementasi strategi TI. 4. Mengembangkan panduan implementasi yang lebih praktis agar mudah diadopsi oleh berbagai jenis organisasi. | AX32: =TRUE() -> TRUE | AY32: =FALSE() -> FALSE | AZ32: =AVERAGE(K32:O32) -> 5 | BA32: =AVERAGE(P32:T32) -> 5 | BB32: =AVERAGE(U32:Y32) -> 5 | BC32: =AVERAGE(Z32:AD32) -> 5 | BD32: =AVERAGE(AE32:AI32) -> 4.8 | BE32: =AVERAGE(AJ32:AN32) -> 5 | BF32: =AVERAGE(AO32:AS32) -> 4.8 | BG32: =IF(AZ32>=4,1,0) -> 1 | BH32: =IF(BA32>=4,1,0) -> 1 | BI32: =IF(BB32>=4,1,0) -> 1 | BJ32: =IF(BC32>=4,1,0) -> 1 | BK32: =IF(BD32>=4,1,0) -> 1 | BL32: =IF(BE32>=4,1,0) -> 1 | BM32: =IF(BF32>=4,1,0) -> 1
A33: 46081.66 | B33: Hasdi | C33: Pria | D33: Other : | E33: 19.Aktivitas Jasa Lainnya | F33: 081510348043 | G33: Tata Kelola TI/ IT Governance, Arsitektur Enterprise, Perencanaan Strategis TI, Audit & Manajemen TI, Pengembang Aplikasi, Infrastructure IT, Cybersecurity | I33: > 20 Tahun | J33: COBIT, ITIL | K33: 4 | L33: 4 | M33: 4 | N33: 4 | O33: 4 | P33: 4 | Q33: 4 | R33: 4 | S33: 4 | T33: 4 | U33: 4 | V33: 4 | W33: 4 | X33: 4 | Y33: 4 | Z33: 4 | AA33: 5 | AB33: 4 | AC33: 4 | AD33: 4 | AF33: 2 | AG33: 4 | AH33: 3 | AI33: 4 | AJ33: 4 | AK33: 2 | AL33: 4 | AM33: 3 | AN33: 4 | AO33: 4 | AP33: 4 | AT33: Ya, sudah menggambarkan | AU33: Tata kelola IT | AV33: Ya, karena organisasi sangat mengandalkan performa IT | AW33: Bisa melibatkan AI dalam pengembangan model | AX33: =FALSE() -> FALSE | AY33: =TRUE() -> TRUE | AZ33: =AVERAGE(K33:O33) -> 4 | BG33: =IF(AZ33>=4,1,0) -> 1
